<?xml version='1.0'?>
<sdf version='1.7'>
  <model name='wow_craft'>
    <enable_wind>true</enable_wind>

    <link name="base_link">
      <visual name="visual">
        <geometry>
          <mesh>
            <uri>model://wow_craft/meshes/wow_craft3.stl</uri>
          </mesh>
        </geometry>
      </visual>
      <collision name="collision">
        <geometry>
          <mesh>
            <uri>model://wow_craft/meshes/100.stl</uri>
          </mesh>
        </geometry>
      </collision>
      <inertial>
        <pose>0 0 0 0 0 0</pose>
        <mass>10.0</mass>
        <inertia>
          <ixx>0.3</ixx>
          <ixy>0</ixy>
          <iyy>0.3</iyy>
          <iyz>0</iyz>
          <izz>0.6</izz>
        </inertia>
      </inertial>
    </link>

    <link name="thruster_1_link">
      <pose>0.28 0 -0.01 0 0 -1.570796</pose>
      <visual name="visual">
        <geometry>
          <mesh>
            <uri>model://wam-v/meshes/engine.dae</uri>
            <scale>0.1 0.1 0.1</scale>
          </mesh>
        </geometry>
      </visual>
      <collision name="engine_vertical_axis_collision">
        <pose>-0.016 0 -0.0215 0 0 0</pose>
        <geometry>
          <box>
            <size>0.01 0.01 0.083</size>
          </box>
        </geometry>
      </collision>
      <collision name="engine_rear_end_collision">
        <pose>-0.034 0 0.012 0 0 0</pose>
        <geometry>
          <box>
            <size>0.015 0.015 0.012</size>
          </box>
        </geometry>
      </collision>
      <inertial>
        <mass>0.1</mass>
        <inertia>
          <ixx>0.0001</ixx>
          <ixy>0</ixy>
          <iyy>0.0001</iyy>
          <iyz>0</iyz>
          <izz>0.0001</izz>
        </inertia>
      </inertial>
    </link>
    <joint name="thruster_1_joint" type="revolute">
      <parent>base_link</parent>
      <child>thruster_1_link</child>
      <axis>
        <xyz>0 0 1</xyz>
        <limit>
          <lower>0</lower>
          <upper>0</upper>
        </limit>
        <dynamics>
          <damping>0.05</damping>
        </dynamics>
      </axis>
    </joint>

    <link name="thruster_1_propeller_link">
      <pose relative_to="thruster_1_propeller_joint">0 0 0 0 0 0</pose>
      <visual name="visual">
        <geometry>
          <mesh>
            <uri>model://wam-v/meshes/propeller.dae</uri>
            <scale>0.1 0.1 0.1</scale>
          </mesh>
        </geometry>
      </visual>
      <collision name="collision">
        <pose>-0.011 0 0 0 1.570796 0</pose>
        <geometry>
          <cylinder>
            <length>0.01</length>
            <radius>0.03</radius>
          </cylinder>
        </geometry>
      </collision>
      <inertial>
        <mass>0.1</mass>
        <inertia>
          <ixx>0.0001</ixx>
          <ixy>0</ixy>
          <iyy>0.0001</iyy>
          <iyz>0</iyz>
          <izz>0.0001</izz>
        </inertia>
      </inertial>
    </link>
    <joint name="thruster_1_propeller_joint" type="revolute">
      <pose relative_to="thruster_1_link">-0.0278156 0 -0.0509371 0 0 0</pose>
      <parent>thruster_1_link</parent>
      <child>thruster_1_propeller_link</child>
      <axis>
        <xyz>1 0 0</xyz>
        <dynamics>
          <damping>0.01</damping>
        </dynamics>
        <limit>
          <lower>-1e+16</lower>
          <upper>1e+16</upper>
        </limit>
      </axis>
    </joint>

    <link name="thruster_2_link">
      <pose>0 0.28 -0.01 0 0 0</pose>
      <visual name="visual">
        <geometry>
          <mesh>
            <uri>model://wam-v/meshes/engine.dae</uri>
            <scale>0.1 0.1 0.1</scale>
          </mesh>
        </geometry>
      </visual>
      <collision name="engine_vertical_axis_collision">
        <pose>-0.016 0 -0.0215 0 0 0</pose>
        <geometry>
          <box>
            <size>0.01 0.01 0.083</size>
          </box>
        </geometry>
      </collision>
      <collision name="engine_rear_end_collision">
        <pose>-0.034 0 0.012 0 0 0</pose>
        <geometry>
          <box>
            <size>0.015 0.015 0.012</size>
          </box>
        </geometry>
      </collision>
      <inertial>
        <mass>0.1</mass>
        <inertia>
          <ixx>0.0001</ixx>
          <ixy>0</ixy>
          <iyy>0.0001</iyy>
          <iyz>0</iyz>
          <izz>0.0001</izz>
        </inertia>
      </inertial>
    </link>
    <joint name="thruster_2_joint" type="revolute">
      <parent>base_link</parent>
      <child>thruster_2_link</child>
      <axis>
        <xyz>0 0 1</xyz>
        <limit>
          <lower>0</lower>
          <upper>0</upper>
        </limit>
        <dynamics>
          <damping>0.05</damping>
        </dynamics>
      </axis>
    </joint>

    <link name="thruster_2_propeller_link">
      <pose relative_to="thruster_2_propeller_joint">0 0 0 0 0 0</pose>
      <visual name="visual">
        <geometry>
          <mesh>
            <uri>model://wam-v/meshes/propeller.dae</uri>
            <scale>0.1 0.1 0.1</scale>
          </mesh>
        </geometry>
      </visual>
      <collision name="collision">
        <pose>-0.011 0 0 0 1.570796 0</pose>
        <geometry>
          <cylinder>
            <length>0.01</length>
            <radius>0.03</radius>
          </cylinder>
        </geometry>
      </collision>
      <inertial>
        <mass>0.1</mass>
        <inertia>
          <ixx>0.0001</ixx>
          <ixy>0</ixy>
          <iyy>0.0001</iyy>
          <iyz>0</iyz>
          <izz>0.0001</izz>
        </inertia>
      </inertial>
    </link>
    <joint name="thruster_2_propeller_joint" type="revolute">
      <pose relative_to="thruster_2_link">-0.0278156 0 -0.0509371 0 0 0</pose>
      <parent>thruster_2_link</parent>
      <child>thruster_2_propeller_link</child>
      <axis>
        <xyz>1 0 0</xyz>
        <dynamics>
          <damping>0.01</damping>
        </dynamics>
        <limit>
          <lower>-1e+16</lower>
          <upper>1e+16</upper>
        </limit>
      </axis>
    </joint>

    <link name="thruster_3_link">
      <pose>-0.28 0 -0.01 0 0 1.570796</pose>
      <visual name="visual">
        <geometry>
          <mesh>
            <uri>model://wam-v/meshes/engine.dae</uri>
            <scale>0.1 0.1 0.1</scale>
          </mesh>
        </geometry>
      </visual>
      <collision name="engine_vertical_axis_collision">
        <pose>-0.016 0 -0.0215 0 0 0</pose>
        <geometry>
          <box>
            <size>0.01 0.01 0.083</size>
          </box>
        </geometry>
      </collision>
      <collision name="engine_rear_end_collision">
        <pose>-0.034 0 0.012 0 0 0</pose>
        <geometry>
          <box>
            <size>0.015 0.015 0.012</size>
          </box>
        </geometry>
      </collision>
      <inertial>
        <mass>0.1</mass>
        <inertia>
          <ixx>0.0001</ixx>
          <ixy>0</ixy>
          <iyy>0.0001</iyy>
          <iyz>0</iyz>
          <izz>0.0001</izz>
        </inertia>
      </inertial>
    </link>
    <joint name="thruster_3_joint" type="revolute">
      <parent>base_link</parent>
      <child>thruster_3_link</child>
      <axis>
        <xyz>0 0 1</xyz>
        <limit>
          <lower>0</lower>
          <upper>0</upper>
        </limit>
        <dynamics>
          <damping>0.05</damping>
        </dynamics>
      </axis>
    </joint>

    <link name="thruster_3_propeller_link">
      <pose relative_to="thruster_3_propeller_joint">0 0 0 0 0 0</pose>
      <visual name="visual">
        <geometry>
          <mesh>
            <uri>model://wam-v/meshes/propeller.dae</uri>
            <scale>0.1 0.1 0.1</scale>
          </mesh>
        </geometry>
      </visual>
      <collision name="collision">
        <pose>-0.011 0 0 0 1.570796 0</pose>
        <geometry>
          <cylinder>
            <length>0.01</length>
            <radius>0.03</radius>
          </cylinder>
        </geometry>
      </collision>
      <inertial>
        <mass>0.1</mass>
        <inertia>
          <ixx>0.0001</ixx>
          <ixy>0</ixy>
          <iyy>0.0001</iyy>
          <iyz>0</iyz>
          <izz>0.0001</izz>
        </inertia>
      </inertial>
    </link>
    <joint name="thruster_3_propeller_joint" type="revolute">
      <pose relative_to="thruster_3_link">-0.0278156 0 -0.0509371 0 0 0</pose>
      <parent>thruster_3_link</parent>
      <child>thruster_3_propeller_link</child>
      <axis>
        <xyz>1 0 0</xyz>
        <dynamics>
          <damping>0.01</damping>
        </dynamics>
        <limit>
          <lower>-1e+16</lower>
          <upper>1e+16</upper>
        </limit>
      </axis>
    </joint>

    <link name="thruster_4_link">
      <pose>0 -0.28 -0.01 0 0 3.141592</pose>
      <visual name="visual">
        <geometry>
          <mesh>
            <uri>model://wam-v/meshes/engine.dae</uri>
            <scale>0.1 0.1 0.1</scale>
          </mesh>
        </geometry>
      </visual>
      <collision name="engine_vertical_axis_collision">
        <pose>-0.016 0 -0.0215 0 0 0</pose>
        <geometry>
          <box>
            <size>0.01 0.01 0.083</size>
          </box>
        </geometry>
      </collision>
      <collision name="engine_rear_end_collision">
        <pose>-0.034 0 0.012 0 0 0</pose>
        <geometry>
          <box>
            <size>0.015 0.015 0.012</size>
          </box>
        </geometry>
      </collision>
      <inertial>
        <mass>0.1</mass>
        <inertia>
          <ixx>0.0001</ixx>
          <ixy>0</ixy>
          <iyy>0.0001</iyy>
          <iyz>0</iyz>
          <izz>0.0001</izz>
        </inertia>
      </inertial>
    </link>
    <joint name="thruster_4_joint" type="revolute">
      <parent>base_link</parent>
      <child>thruster_4_link</child>
      <axis>
        <xyz>0 0 1</xyz>
        <limit>
          <lower>0</lower>
          <upper>0</upper>
        </limit>
        <dynamics>
          <damping>0.05</damping>
        </dynamics>
      </axis>
    </joint>

    <link name="thruster_4_propeller_link">
      <pose relative_to="thruster_4_propeller_joint">0 0 0 0 0 0</pose>
      <visual name="visual">
        <geometry>
          <mesh>
            <uri>model://wam-v/meshes/propeller.dae</uri>
            <scale>0.1 0.1 0.1</scale>
          </mesh>
        </geometry>
      </visual>
      <collision name="collision">
        <pose>-0.011 0 0 0 1.570796 0</pose>
        <geometry>
          <cylinder>
            <length>0.01</length>
            <radius>0.03</radius>
          </cylinder>
        </geometry>
      </collision>
      <inertial>
        <mass>0.1</mass>
        <inertia>
          <ixx>0.0001</ixx>
          <ixy>0</ixy>
          <iyy>0.0001</iyy>
          <iyz>0</iyz>
          <izz>0.0001</izz>
        </inertia>
      </inertial>
    </link>
    <joint name="thruster_4_propeller_joint" type="revolute">
      <pose relative_to="thruster_4_link">-0.0278156 0 -0.0509371 0 0 0</pose>
      <parent>thruster_4_link</parent>
      <child>thruster_4_propeller_link</child>
      <axis>
        <xyz>1 0 0</xyz>
        <dynamics>
          <damping>0.01</damping>
        </dynamics>
        <limit>
          <lower>-1e+16</lower>
          <upper>1e+16</upper>
        </limit>
      </axis>
    </joint>

    <!-- Sensors -->
    <link name="imu_link">
      <inertial>
        <pose>0 0 0 0 0 0</pose>
        <mass>0.15</mass>
        <inertia>
          <ixx>0.00001</ixx>
          <ixy>0</ixy>
          <ixz>0</ixz>
          <iyy>0.00002</iyy>
          <iyz>0</iyz>
          <izz>0.00002</izz>
        </inertia>
      </inertial>
      <sensor name="imu_sensor" type="imu">
        <pose>0 0 0 0 0 0</pose>
        <always_on>1</always_on>
        <update_rate>1000.0</update_rate>
      </sensor>
    </link>
    <joint name="imu_joint" type="revolute">
      <child>imu_link</child>
      <parent>base_link</parent>
      <axis>
        <xyz>0 0 1</xyz>
        <limit>
          <lower>0</lower>
          <upper>0</upper>
          <effort>0</effort>
          <velocity>0</velocity>
        </limit>
        <dynamics>
          <damping>1.0</damping>
        </dynamics>
      </axis>
    </joint>

    <!-- Joint state and force plugins -->
    <plugin filename="gz-sim-joint-state-publisher-system"
      name="gz::sim::systems::JointStatePublisher">
    </plugin>
    <plugin filename="gz-sim-apply-joint-force-system"
      name="gz::sim::systems::ApplyJointForce">
      <joint_name>thruster_1_joint</joint_name>
    </plugin>
    <plugin filename="gz-sim-apply-joint-force-system"
      name="gz::sim::systems::ApplyJointForce">
      <joint_name>thruster_2_joint</joint_name>
    </plugin>
    <plugin filename="gz-sim-apply-joint-force-system"
      name="gz::sim::systems::ApplyJointForce">
      <joint_name>thruster_3_joint</joint_name>
    </plugin>
    <plugin filename="gz-sim-apply-joint-force-system"
      name="gz::sim::systems::ApplyJointForce">
      <joint_name>thruster_4_joint</joint_name>
    </plugin>


    <!-- Thruster plugins -->
    <plugin
        filename="gz-sim-thruster-system"
        name="gz::sim::systems::Thruster">
      <namespace>wow_craft</namespace>
      <joint_name>thruster_1_propeller_joint</joint_name>
      <use_angvel_cmd>0</use_angvel_cmd>
      <fluid_density>1000</fluid_density>
      <propeller_diameter>0.06</propeller_diameter>
      <thrust_coefficient>0.01</thrust_coefficient>
      <velocity_control>1</velocity_control>
      <!-- <p_gain>1.0</p_gain>
      <i_gain>0.0</i_gain>
      <d_gain>0.0</d_gain> -->
      <max_thrust_cmd>200.0</max_thrust_cmd>
      <min_thrust_cmd>-200.0</min_thrust_cmd>
    </plugin>

    <plugin
        filename="gz-sim-thruster-system"
        name="gz::sim::systems::Thruster">
      <namespace>wow_craft</namespace>
      <joint_name>thruster_2_propeller_joint</joint_name>
      <use_angvel_cmd>0</use_angvel_cmd>
      <fluid_density>1000</fluid_density>
      <propeller_diameter>0.06</propeller_diameter>
      <thrust_coefficient>0.01</thrust_coefficient>
      <velocity_control>1</velocity_control>
      <!-- <p_gain>1.0</p_gain>
      <i_gain>0.0</i_gain>
      <d_gain>0.0</d_gain> -->
      <max_thrust_cmd>200.0</max_thrust_cmd>
      <min_thrust_cmd>-200.0</min_thrust_cmd>
    </plugin>

    <plugin
        filename="gz-sim-thruster-system"
        name="gz::sim::systems::Thruster">
      <namespace>wow_craft</namespace>
      <joint_name>thruster_3_propeller_joint</joint_name>
      <use_angvel_cmd>0</use_angvel_cmd>
      <fluid_density>1000</fluid_density>
      <propeller_diameter>0.06</propeller_diameter>
      <thrust_coefficient>0.01</thrust_coefficient>
      <velocity_control>1</velocity_control>
      <!-- <p_gain>1.0</p_gain>
      <i_gain>0.0</i_gain>
      <d_gain>0.0</d_gain> -->
      <max_thrust_cmd>200.0</max_thrust_cmd>
      <min_thrust_cmd>-200.0</min_thrust_cmd>
    </plugin>

    <plugin
        filename="gz-sim-thruster-system"
        name="gz::sim::systems::Thruster">
      <namespace>wow_craft</namespace>
      <joint_name>thruster_4_propeller_joint</joint_name>
      <use_angvel_cmd>0</use_angvel_cmd>
      <fluid_density>1000</fluid_density>
      <propeller_diameter>0.06</propeller_diameter>
      <thrust_coefficient>0.01</thrust_coefficient>
      <velocity_control>1</velocity_control>
      <!-- <p_gain>1.0</p_gain>
      <i_gain>0.0</i_gain>
      <d_gain>0.0</d_gain> -->
      <max_thrust_cmd>200.0</max_thrust_cmd>
      <min_thrust_cmd>-200.0</min_thrust_cmd>
    </plugin>

    <!-- Hydrodynamics plugin -->
    <plugin
        filename="gz-waves1-hydrodynamics-system"
        name="gz::sim::systems::Hydrodynamics">
        <enable>wow_craft</enable>
      
        <hydrodynamics>
          <damping_on>1</damping_on>
          <viscous_drag_on>1</viscous_drag_on>
          <pressure_drag_on>1</pressure_drag_on>

          <!-- Linear and Angular Damping -->
          <cDampL1>1.0E-6</cDampL1>
          <cDampL2>1.0E-6</cDampL2>
          <cDampR1>1.0E-6</cDampR1>
          <cDampR2>1.0E-6</cDampR2>

          <!-- 'Pressure' Drag -->
          <cPDrag1>50</cPDrag1>
          <cPDrag2>50</cPDrag2>
          <fPDrag>1.0</fPDrag>
          <cSDrag1>50</cSDrag1>
          <cSDrag2>50</cSDrag2>
          <fSDrag>0.4</fSDrag>
          <vRDrag>1.0</vRDrag>
        </hydrodynamics>
    </plugin>


    <!-- ArduPilot plugin -->
    <plugin name="ArduPilotPlugin" filename="ArduPilotPlugin">
      <fdm_addr>127.0.0.1</fdm_addr>
      <fdm_port_in>9002</fdm_port_in>
      <connectionTimeoutMaxCount>5</connectionTimeoutMaxCount>
      <lock_step>1</lock_step>
      <modelXYZToAirplaneXForwardZDown>0 0 0 3.141593 0 0</modelXYZToAirplaneXForwardZDown>
      <gazeboXYZToNED>0 0 0 3.141593 0 1.57079632</gazeboXYZToNED>
      <imuName>imu_sensor</imuName>

      <!--
        SERVO1_FUNCTION 26 (GroundSteering)
      -->
      <control channel="0">
        <jointName>thruster_1_joint</jointName>
        <useForce>1</useForce>
        <multiplier>3.1415926</multiplier>
        <offset>-0.5</offset>
        <servo_min>1000</servo_min>
        <servo_max>2000</servo_max>
        <type>POSITION</type>
        <p_gain>500.0</p_gain>
        <i_gain>0</i_gain>
        <d_gain>10</d_gain>
        <i_max>-1</i_max>
        <i_min>0</i_min>
        <cmd_max>5000.0</cmd_max>
        <cmd_min>-5000.0</cmd_min>
      </control>

      <control channel="0">
        <jointName>thruster_2_joint</jointName>
        <useForce>1</useForce>
        <multiplier>3.1415926</multiplier>
        <offset>-0.5</offset>
        <servo_min>1000</servo_min>
        <servo_max>2000</servo_max>
        <type>POSITION</type>
        <p_gain>500.0</p_gain>
        <i_gain>0</i_gain>
        <d_gain>10</d_gain>
        <i_max>-1</i_max>
        <i_min>0</i_min>
        <cmd_max>5000.0</cmd_max>
        <cmd_min>-5000.0</cmd_min>
      </control>

      <control channel="0">
        <jointName>thruster_3_joint</jointName>
        <useForce>1</useForce>
        <multiplier>3.1415926</multiplier>
        <offset>-0.5</offset>
        <servo_min>1000</servo_min>
        <servo_max>2000</servo_max>
        <type>POSITION</type>
        <p_gain>500.0</p_gain>
        <i_gain>0</i_gain>
        <d_gain>10</d_gain>
        <i_max>-1</i_max>
        <i_min>0</i_min>
        <cmd_max>5000.0</cmd_max>
        <cmd_min>-5000.0</cmd_min>
      </control>

      <control channel="0">
        <jointName>thruster_4_joint</jointName>
        <useForce>1</useForce>
        <multiplier>3.1415926</multiplier>
        <offset>-0.5</offset>
        <servo_min>1000</servo_min>
        <servo_max>2000</servo_max>
        <type>POSITION</type>
        <p_gain>500.0</p_gain>
        <i_gain>0</i_gain>
        <d_gain>10</d_gain>
        <i_max>-1</i_max>
        <i_min>0</i_min>
        <cmd_max>5000.0</cmd_max>
        <cmd_min>-5000.0</cmd_min>
      </control>

      <control channel="2">
        <jointName>thruster_1_propeller_joint</jointName>
        <useForce>1</useForce>
        <multiplier>3000</multiplier>
        <offset>-0.5</offset>
        <servo_min>1000</servo_min>
        <servo_max>2000</servo_max>
        <type>COMMAND</type>
        <cmd_topic>/model/wow_craft/joint/thruster_1_propeller_joint/cmd_thrust</cmd_topic>
      </control>

      <control channel="2">
        <jointName>thruster_2_propeller_joint</jointName>
        <useForce>1</useForce>
        <multiplier>3000</multiplier>
        <offset>-0.5</offset>
        <servo_min>1000</servo_min>
        <servo_max>2000</servo_max>
        <type>COMMAND</type>
        <cmd_topic>/model/wow_craft/joint/thruster_2_propeller_joint/cmd_thrust</cmd_topic>
      </control>

      <control channel="2">
        <jointName>thruster_3_propeller_joint</jointName>
        <useForce>1</useForce>
        <multiplier>3000</multiplier>
        <offset>-0.5</offset>
        <servo_min>1000</servo_min>
        <servo_max>2000</servo_max>
        <type>COMMAND</type>
        <cmd_topic>/model/wow_craft/joint/thruster_3_propeller_joint/cmd_thrust</cmd_topic>
      </control>

      <control channel="2">
        <jointName>thruster_4_propeller_joint</jointName>
        <useForce>1</useForce>
        <multiplier>3000</multiplier>
        <offset>-0.5</offset>
        <servo_min>1000</servo_min>
        <servo_max>2000</servo_max>
        <type>COMMAND</type>
        <cmd_topic>/model/wow_craft/joint/thruster_4_propeller_joint/cmd_thrust</cmd_topic>
      </control>
    </plugin>
  </model>
</sdf>